#VRML_SIM R2021a utf8
WorldInfo {
  coordinateSystem "NUE"
  contactProperties [
    ContactProperties {
    }
  ]
}
Viewpoint {
  orientation 0.19066628032991415 0.9429144742422753 0.2730543239166308 4.306123469363618
  position -8.565701182971253 5.547286110783087 -0.9690044747834787
}
DEF cylinder Solid {
  translation -1.64 0.246661 0.83
  rotation 1.8366149431701162e-06 9.146982105132404e-12 0.9999999999983133 6.787947757080456e-06
  children [
    DEF cylinder Shape {
      appearance Appearance {
        material Material {
          diffuseColor 0.576471 0.796078 0.8
          emissiveColor 0.517647 0.509804 0.588235
          shininess 0.6
        }
      }
      geometry Cylinder {
        height 0.8
        radius 0.26
        subdivision 38
      }
    }
  ]
  boundingObject USE cylinder
  physics Physics {
  }
  recognitionColors [
    1 0 0
  ]
}
Cypress {
  translation -11.7424 -0.99 9.6301
  rotation 0 1 0 2.0944
  name "cypress tree(2)"
}
Cypress {
  translation 7.39 -0.59 4.808
  rotation 0 1 0 2.0944
  name "cypress tree(1)"
}
UnevenTerrain {
  translation -0.66 -3.54 0
}
SoccerBall {
  hidden linearVelocity_0 -0.01866424679035231 -8.758811139232424e-08 5.162979009159781e-08
  hidden angularVelocity_0 4.607394704035777e-07 2.582263506409091e-07 0.16655844952311588
  translation 0.24555184587560297 -0.007940842304004523 6.2189376358713785e-06
  rotation 4.437059191761455e-07 -4.92357189583552e-07 0.9999999999997804 1.1741098673459978
}
Cypress {
  translation -10.4066 -0.88 -4.7558
  rotation 0 1 0 2.0944
  name "cypress tree(3)"
}
HouseWithGarage {
  translation 0 -1.11 11.97
}
TexturedBackgroundLight {
  luminosity 0
}
DEF wall_1 Solid {
  translation 0 0 -2.45
  children [
    DEF wall1 Shape {
      appearance Appearance {
        material Material {
          diffuseColor 0.262745 0.262745 0.262745
        }
      }
      geometry Box {
        size 5 0.5 0.1
      }
    }
  ]
  name "solid1"
  boundingObject USE wall1
}
DEF wall_2 Solid {
  translation 0 0 2.45
  children [
    DEF wall2 Shape {
      appearance Appearance {
        material Material {
          diffuseColor 0.262745 0.262745 0.262745
        }
      }
      geometry Box {
        size 5 0.5 0.1
      }
    }
  ]
  name "solid2"
  boundingObject USE wall2
}
DEF wall_3 Solid {
  translation -2.5 0 2.03924e-08
  rotation 0 1 0 -1.5707953071795862
  children [
    DEF wall3 Shape {
      appearance Appearance {
        material Material {
          diffuseColor 0.282353 0.282353 0.282353
        }
      }
      geometry Box {
        size 5 0.5 0.1
      }
    }
  ]
  name "solid3"
  boundingObject USE wall3
}
DEF wall_4 Solid {
  translation 2.53 0 -5.10833e-06
  rotation 0 1 0 -1.5707953071795862
  children [
    DEF wall4 Shape {
      appearance Appearance {
        material Material {
          diffuseColor 0.345098 0.345098 0.345098
        }
      }
      geometry Box {
        size 5 0.5 0.1
      }
    }
  ]
  name "solid4"
  boundingObject USE wall4
}
DirectionalLight {
  direction 0 -1 -0.3
  intensity 1.5
  castShadows TRUE
}
Background {
  skyColor [
    0.862745 0.862745 0.862745
  ]
  bottomUrl [
    ""
  ]
  frontUrl [
    ""
  ]
  backIrradianceUrl [
    ""
  ]
  bottomIrradianceUrl [
    ""
  ]
}
DEF cylinder Solid {
  translation -1417.745719390173 -7532841.643484759 -34.83003475144508
  rotation -0.9636165858350001 -0.08008426671511325 0.25500899146579187 3.122586039104845
  children [
    DEF cylinder Shape {
      appearance Appearance {
        material Material {
          diffuseColor 0 1 1
        }
      }
      geometry Cylinder {
        height 0.5
        radius 0.19
        subdivision 38
      }
    }
  ]
  name "solidcylinder"
  boundingObject Cylinder {
    height 0.5
    radius 0.19
  }
  physics Physics {
    mass 20
  }
  recognitionColors [
    1 0 0
  ]
  linearVelocity -1.123326812057191 -12156.912644638003 -0.029547731065917918
  angularVelocity -1111.9196818765777 -761.8484112064228 9908.74470452225
}
DEF sphere Solid {
  translation 0.301992 0.144632 -1.9751
  rotation -0.9729911129483524 0.045209809388280744 0.22637218746701612 2.332566906662847
  children [
    DEF sphere Shape {
      appearance Appearance {
        material Material {
          diffuseColor 1 0 1
        }
      }
      geometry Sphere {
        radius 0.2
        subdivision 5
      }
    }
  ]
  name "solidsphere"
  boundingObject Sphere {
    radius 0.2
    subdivision 5
  }
  physics Physics {
    density -1
    mass 1
  }
  recognitionColors [
    1 0 0
  ]
}
DEF wheel Solid {
  translation -1.3 -0.05 -2.38
  children [
    DEF wheel Transform {
      translation 0.02 0 0.84
      children [
        DEF wheel1 Shape {
          appearance Appearance {
            material Material {
              diffuseColor 1 0 0
            }
          }
          geometry Cylinder {
            height 0.2
            radius 0.2
          }
        }
      ]
    }
    DEF wheel2 Transform {
      translation 0.02 0.35 0.85
      children [
        DEF wheel2 Shape {
          appearance Appearance {
            material Material {
              diffuseColor 1 1 0
            }
          }
          geometry Cylinder {
            height 0.5
            radius 0.05
          }
        }
      ]
    }
  ]
  name "solidwheel"
  boundingObject Group {
    children [
      Transform {
        translation 0.02 0.35 0.85
        children [
          USE wheel2
        ]
      }
      Transform {
        translation 0.02 0 0.84
        children [
          USE wheel1
        ]
      }
    ]
  }
  recognitionColors [
    1 0 0
  ]
}
DEF floorsolid Solid {
  translation 0.0499994 -0.17 0.01
  rotation -2.3464099999870814e-06 0.9999999999944944 2.3464099999870814e-06 1.5708
  children [
    DEF floor Shape {
      appearance Appearance {
        material Material {
          diffuseColor 0.0666667 0.0627451 0.0509804
        }
        texture ImageTexture {
          url [
            "textures/desktop_wood.jpg"
          ]
        }
      }
      geometry Box {
        size 5 0.1 5
      }
    }
  ]
  name "solid(1)"
  boundingObject Group {
    children [
      DEF floor Shape {
        appearance Appearance {
          material Material {
          }
        }
        geometry Box {
          size 5 0.1 5
        }
      }
    ]
  }
}
Robot {
  translation 1.41349 0.0223898 1.26449
  rotation 9.626257637899464e-06 0.999999971434138 -0.00023882851193841919 -1.8829079842276966
  scale 4 4 4
  children [
    DEF Camera Solid {
      translation 0 0 0.12
      children [
        Shape {
          appearance PBRAppearance {
            baseColor 0.666667 0 1
          }
          geometry Sphere {
            radius 0.015
          }
        }
        Camera {
          translation 0.00100013 0.07 0.02
          rotation 0 1 0 -3.1415853071795863
          name "CAM"
          fieldOfView 1
          width 640
          height 640
          recognition Recognition {
            frameColor 0.705882 0 0
            frameThickness 9
          }
        }
      ]
      name "solid(4)"
    }
    DistanceSensor {
      translation 0.02 0 0.1
      rotation 0 -1 0 1.27
      children [
        Shape {
          appearance PBRAppearance {
            baseColor 0.952941 0.317647 0
          }
          geometry Box {
            size 0.01 0.01 0.01
          }
        }
      ]
      name "ds_right"
    }
    DistanceSensor {
      translation -0.02 0 0.1
      rotation 0 -1 0 1.87
      children [
        Shape {
          appearance PBRAppearance {
            baseColor 0.952941 0.317647 0
          }
          geometry Box {
            size 0.01 0.01 0.01
          }
        }
      ]
      name "ds_left"
    }
    HingeJoint {
      jointParameters HingeJointParameters {
        position 3870.1288926369675
        anchor 0.06 -3.0304913774206853e-06 0.04999999990816122
      }
      device [
        RotationalMotor {
          name "wheel1"
        }
      ]
      endPoint Solid {
        translation 0.06 -1.47450343349766e-07 0.049999066124249994
        rotation -0.15424468017216184 0.15412189988049987 0.9759380198638706 1.5943540194881298
        children [
          DEF robot_wheel Shape {
            appearance PBRAppearance {
              baseColor 1 0.666667 1
            }
            geometry Cylinder {
              height 0.02
              radius 0.04
            }
          }
        ]
        boundingObject USE robot_wheel
        physics Physics {
        }
      }
    }
    HingeJoint {
      jointParameters HingeJointParameters {
        position 1520.82830963155
        anchor -0.06 -3.03242521797931e-06 0.049999999908043984
      }
      device [
        RotationalMotor {
          name "wheel2"
        }
      ]
      endPoint Solid {
        translation -0.060000000205182695 5.986969676240291e-05 0.05001927902037233
        rotation 0.14669789275722228 -0.14658085808911384 0.9782605891593761 1.5919810702481725
        children [
          DEF robot_wheel Shape {
            appearance PBRAppearance {
              baseColor 1 0.666667 1
            }
            geometry Cylinder {
              height 0.02
              radius 0.04
            }
          }
        ]
        name "solid(1)"
        boundingObject USE robot_wheel
        physics Physics {
        }
      }
    }
    HingeJoint {
      jointParameters HingeJointParameters {
        position 3870.122966053313
        anchor 0.05999999999999999 -3.0291739447010566e-06 -0.04999999990824105
      }
      device [
        RotationalMotor {
          name "wheel3"
        }
      ]
      endPoint Solid {
        translation 0.06 -1.5302616229476142e-07 -0.050000950523162814
        rotation -0.15706754708526485 0.15694251976360674 0.9750378613894272 1.5952765310089732
        children [
          DEF robot_wheel Shape {
            appearance PBRAppearance {
              baseColor 1 0.666667 1
            }
            geometry Cylinder {
              height 0.02
              radius 0.04
            }
          }
        ]
        name "solid(2)"
        boundingObject USE robot_wheel
        physics Physics {
        }
      }
    }
    HingeJoint {
      jointParameters HingeJointParameters {
        position 1520.8352416525909
        anchor -0.06000000000000001 -3.029297765400883e-06 -0.04999999990823356
      }
      device [
        RotationalMotor {
          name "wheel4"
        }
      ]
      endPoint Solid {
        translation -0.06 -1.3923609647738813e-07 -0.049999092059948014
        rotation 0.15001546154108944 -0.14989604774930593 0.9772545912748386 1.5930062498984499
        children [
          DEF robot_wheel Shape {
            appearance PBRAppearance {
              baseColor 1 0.666667 1
            }
            geometry Cylinder {
              height 0.02
              radius 0.04
            }
          }
        ]
        name "solid(3)"
        boundingObject USE robot_wheel
        physics Physics {
        }
      }
    }
    DEF Robot_Body Shape {
      appearance PBRAppearance {
        baseColor 0 0 0
      }
      geometry Box {
        size 0.1 0.05 0.2
      }
    }
  ]
  boundingObject USE Robot_Body
  physics Physics {
  }
  controller "461"
}
OilBarrel {
  translation 1.6 -0.0199916 0.25
  rotation 1 0 0 3.14159
  height 0.3
  radius 0.1
}
TableWithUmbrella {
  translation -7.21166 -0.52 -3.00891
  rotation 0 1 0 2.61799
}
Swing {
  translation 8.26786 -0.09 -0.906756
  rotation 0 1 0 0.785398
}
